Workbook

Sheet soc_min_eval
A1: elapsed_nanos | B1: objective_0 | C1: objective_1 | D1: objective_2 | E1: objective_4 | F1: constraint
A2: 0 | B2: 1.0 | C2: 6.0 | D2: 0.0 | E2: -8.0 | F2: 1.0
A3: 801700 | B3: 1.0 | C3: 3.0 | D3: 0.0 | E3: -6.0 | F3: 1.0
A4: 3000800 | B4: 0.0 | C4: 3.0 | D4: 0.0 | E4: -6.0 | F4: 3.0
A5: 4131400 | B5: 0.0 | C5: 2.0 | D5: 0.0 | E5: -7.0 | F5: 5.0
A6: 8110300 | B6: 0.0 | C6: 1.0 | D6: 3.0 | E6: -6.0 | F6: 5.0
A7: 473361700 | B7: 0.0 | C7: 3.0 | D7: 0.0 | E7: -9.0 | F7: 6.0
A8: 1367225400 | B8: 1.0 | C8: 5.0 | D8: 0.0 | E8: -10.0 | F8: 4.0
A9: 1867918200 | B9: 3.0 | C9: 5.0 | D9: 0.0 | E9: -11.0 | F9: 3.0
A10: 3198435300 | B10: 3.0 | C10: 5.0 | D10: 0.0 | E10: -12.0 | F10: 4.0
A11: 5720277900 | B11: 5.0 | C11: 6.0 | D11: 0.0 | E11: -13.0 | F11: 2.0
A12: 9440654400 | B12: 1.0 | C12: 7.0 | D12: 3.0 | E12: -14.0 | F12: 3.0
A13: 18831606900 | B13: 6.0 | C13: 5.0 | D13: 0.0 | E13: -15.0 | F13: 2.0
... A16: 63985869300 | B16: 3.0 | C16: 10.0 | D16: 0.0 | E16: -18.0 | F16: 2.0

Sheet soc_max_eval
A1: elapsed_nanos | B1: objective_0 | C1: objective_1 | D1: objective_3 | E1: objective_4 | F1: constraint
A2: 0 | B2: 1.0 | C2: 6.0 | D2: 0.0 | E2: -8.0 | F2: 1.0
A3: 799400 | B3: 1.0 | C3: 3.0 | D3: 0.0 | E3: -6.0 | F3: 1.0
A4: 3522800 | B4: 0.0 | C4: 3.0 | D4: 0.0 | E4: -6.0 | F4: 3.0
A5: 4643800 | B5: 0.0 | C5: 2.0 | D5: 0.0 | E5: -7.0 | F5: 5.0
A6: 8621600 | B6: 0.0 | C6: 1.0 | D6: -3.0 | E6: -6.0 | F6: 5.0
A7: 506308200 | B7: 0.0 | C7: 7.0 | D7: 0.0 | E7: -9.0 | F7: 2.0
A8: 927596000 | B8: 2.0 | C8: 4.0 | D8: 0.0 | E8: -10.0 | F8: 4.0
A9: 1901816300 | B9: 3.0 | C9: 4.0 | D9: 0.0 | E9: -11.0 | F9: 4.0
A10: 2093571400 | B10: 3.0 | C10: 5.0 | D10: 0.0 | E10: -12.0 | F10: 4.0
A11: 2137841500 | B11: 0.0 | C11: 1.0 | D11: -4.0 | E11: -7.0 | F11: 1.0
A12: 3501206000 | B12: 4.0 | C12: 5.0 | D12: 0.0 | E12: -13.0 | F12: 4.0
A13: 3774177800 | B13: 0.0 | C13: 2.0 | D13: -5.0 | E13: -9.0 | F13: 2.0
... A21: 77629039600 | B21: 4.0 | C21: 9.0 | D21: 0.0 | E21: -20.0 | F21: 2.0

Sheet cra_eval
A1: elapsed_nanos | B1: objective_0 | C1: objective_1 | D1: objective_4 | E1: objective_5 | F1: constraint
A2: 0 | B2: 0.0 | C2: 44.0 | D2: -9.0 | E2: -20.0 | F2: 9.0
A3: 1077000 | B3: 0.0 | C3: 52.0 | D3: -14.0 | E3: -19.0 | F3: 8.0
A4: 2291900 | B4: 2.0 | C4: 24.0 | D4: -6.0 | E4: -20.0 | F4: 9.0
A5: 6323200 | B5: 7.0 | C5: 12.0 | D5: -7.0 | E5: -21.0 | F5: 10.0
A6: 9600000 | B6: 4.0 | C6: 10.0 | D6: -6.0 | E6: -21.0 | F6: 10.0
A7: 19858900 | B7: 0.0 | C7: 48.0 | D7: -16.0 | E7: -19.0 | F7: 8.0
A8: 23013600 | B8: 0.0 | C8: 44.0 | D8: -18.0 | E8: -19.0 | F8: 8.0
A9: 23755399 | B9: 0.0 | C9: 46.0 | D9: -19.0 | E9: -19.0 | F9: 8.0
A10: 27447600 | B10: 0.0 | C10: 40.0 | D10: -26.0 | E10: -19.0 | F10: 8.0
A11: 67712199 | B11: 9.0 | C11: 8.0 | D11: -6.0 | E11: -21.0 | F11: 10.0
A12: 200667400 | B12: 0.0 | C12: 72.0 | D12: -12.0 | E12: -19.0 | F12: 7.0
A13: 203221000 | B13: 0.0 | C13: 48.0 | D13: -31.0 | E13: -19.0 | F13: 7.0
... A30: 41787024200 | B30: 9.0 | C30: 2.0 | D30: -14.0 | E30: -22.0 | F30: 8.0

Sheet eval
A1: elapsed_nanos | B1: objective_0 | C1: objective_1 | D1: objective_4 | E1: objective_5 | F1: constraint | V1: t (s) | W1: obj_1 | X1: obj_2 | Y1: obj_3 | Z1: size | AA1: violation
A2: 0 | B2: 0.0 | C2: 44.0 | D2: -9.0 | E2: -20.0 | F2: 9.0 | H2: =evaluation_run_0__43[[#This Row],[elapsed_nanos]]/10^9 -> 0 | I2: =VALUE(_xlfn.TEXTBEFORE(evaluation_run_0__43[[#This Row],[objective_0]], ".")) -> 0 | J2: =VALUE(_xlfn.TEXTBEFORE(evaluation_run_0__43[[#This Row],[objective_1]], ".")) -> 44 | K2: =VALUE(_xlfn.TEXTBEFORE(evaluation_run_0__43[[#This Row],[objective_4]], ".")) -> -9 | L2: =VALUE(_xlfn.TEXTBEFORE(evaluation_run_0__43[[#This Row],[objective_5]], ".")) -> -20 | M2: =VALUE(_xlfn.TEXTBEFORE(evaluation_run_0__43[[#This Row],[constraint]], ".")) -> 9 | P2: =I2 -> 0 | Q2: =J2 -> 44 | R2: =K2 -> -9 | S2: =L2+22 -> 2 | T2: =M2 -> 9 | V2: =evaluation_run_0__43[[#This Row],[elapsed_nanos]]/10^9 -> 0 | W2: =IF(P$34=0,0,P34/P$34) -> 0 | X2: =IF(Q$34=0,0,Q34/Q$34) -> 1 | Y2: =IF(R$34=0,0,R34/R$34) -> 1 | Z2: =IF(S$34=0,0,S34/S$34) -> 1 | AA2: =IF(T$34=0,0,T34/T$34) -> 1
A3: 1077000 | B3: 0.0 | C3: 52.0 | D3: -14.0 | E3: -19.0 | F3: 8.0 | H3: =evaluation_run_0__43[[#This Row],[elapsed_nanos]]/10^9 -> 0.001077 | I3: =VALUE(_xlfn.TEXTBEFORE(evaluation_run_0__43[[#This Row],[objective_0]], ".")) -> 0 | J3: =VALUE(_xlfn.TEXTBEFORE(evaluation_run_0__43[[#This Row],[objective_1]], ".")) -> 52 | K3: =VALUE(_xlfn.TEXTBEFORE(evaluation_run_0__43[[#This Row],[objective_4]], ".")) -> -14 | L3: =VALUE(_xlfn.TEXTBEFORE(evaluation_run_0__43[[#This Row],[objective_5]], ".")) -> -19 | M3: =VALUE(_xlfn.TEXTBEFORE(evaluation_run_0__43[[#This Row],[constraint]], ".")) -> 8 | P3: =MIN(I3,P2) -> 0 | Q3: =MIN(J3,Q2) -> 44 | R3: =MIN(K3,R2) -> -14 | S3: =MIN(L3+22,S2) -> 2 | T3: =MIN(M3,T2) -> 8 | V3: =evaluation_run_0__43[[#This Row],[elapsed_nanos]]/10^9 -> 0.001077 | W3: =IF(P$34=0,0,P35/P$34) -> 0 | X3: =IF(Q$34=0,0,Q35/Q$34) -> 1 | Y3: =IF(R$34=0,0,R35/R$34) -> 0.86842105 | Z3: =IF(S$34=0,0,S35/S$34) -> 1 | AA3: =IF(T$34=0,0,T35/T$34) -> 0.88888889
A4: 2291900 | B4: 2.0 | C4: 24.0 | D4: -6.0 | E4: -20.0 | F4: 9.0 | H4: =evaluation_run_0__43[[#This Row],[elapsed_nanos]]/10^9 -> 0.0022919 | I4: =VALUE(_xlfn.TEXTBEFORE(evaluation_run_0__43[[#This Row],[objective_0]], ".")) -> 2 | J4: =VALUE(_xlfn.TEXTBEFORE(evaluation_run_0__43[[#This Row],[objective_1]], ".")) -> 24 | K4: =VALUE(_xlfn.TEXTBEFORE(evaluation_run_0__43[[#This Row],[objective_4]], ".")) -> -6 | L4: =VALUE(_xlfn.TEXTBEFORE(evaluation_run_0__43[[#This Row],[objective_5]], ".")) -> -20 | M4: =VALUE(_xlfn.TEXTBEFORE(evaluation_run_0__43[[#This Row],[constraint]], ".")) -> 9 | P4: =MIN(I4,P3) -> 0 | Q4: =MIN(J4,Q3) -> 24 | R4: =MIN(K4,R3) -> -14 | S4: =MIN(L4+22,S3) -> 2 | T4: =MIN(M4,T3) -> 8 | V4: =evaluation_run_0__43[[#This Row],[elapsed_nanos]]/10^9 -> 0.0022919 | W4: =IF(P$34=0,0,P36/P$34) -> 0 | X4: =IF(Q$34=0,0,Q36/Q$34) -> 0.54545455 | Y4: =IF(R$34=0,0,R36/R$34) -> 0.86842105 | Z4: =IF(S$34=0,0,S36/S$34) -> 1 | AA4: =IF(T$34=0,0,T36/T$34) -> 0.88888889
A5: 6323200 | B5: 7.0 | C5: 12.0 | D5: -7.0 | E5: -21.0 | F5: 10.0 | H5: =evaluation_run_0__43[[#This Row],[elapsed_nanos]]/10^9 -> 0.0063232 | I5: =VALUE(_xlfn.TEXTBEFORE(evaluation_run_0__43[[#This Row],[objective_0]], ".")) -> 7 | J5: =VALUE(_xlfn.TEXTBEFORE(evaluation_run_0__43[[#This Row],[objective_1]], ".")) -> 12 | K5: =VALUE(_xlfn.TEXTBEFORE(evaluation_run_0__43[[#This Row],[objective_4]], ".")) -> -7 | L5: =VALUE(_xlfn.TEXTBEFORE(evaluation_run_0__43[[#This Row],[objective_5]], ".")) -> -21 | M5: =VALUE(_xlfn.TEXTBEFORE(evaluation_run_0__43[[#This Row],[constraint]], ".")) -> 10 | P5: =MIN(I5,P4) -> 0 | Q5: =MIN(J5,Q4) -> 12 | R5: =MIN(K5,R4) -> -14 | S5: =MIN(L5+22,S4) -> 1 | T5: =MIN(M5,T4) -> 8 | V5: =evaluation_run_0__43[[#This Row],[elapsed_nanos]]/10^9 -> 0.0063232 | W5: =IF(P$34=0,0,P37/P$34) -> 0 | X5: =IF(Q$34=0,0,Q37/Q$34) -> 0.27272727 | Y5: =IF(R$34=0,0,R37/R$34) -> 0.86842105 | Z5: =IF(S$34=0,0,S37/S$34) -> 0.5 | AA5: =IF(T$34=0,0,T37/T$34) -> 0.88888889
A6: 9600000 | B6: 4.0 | C6: 10.0 | D6: -6.0 | E6: -21.0 | F6: 10.0 | H6: =evaluation_run_0__43[[#This Row],[elapsed_nanos]]/10^9 -> 0.0096 | I6: =VALUE(_xlfn.TEXTBEFORE(evaluation_run_0__43[[#This Row],[objective_0]], ".")) -> 4 | J6: =VALUE(_xlfn.TEXTBEFORE(evaluation_run_0__43[[#This Row],[objective_1]], ".")) -> 10 | K6: =VALUE(_xlfn.TEXTBEFORE(evaluation_run_0__43[[#This Row],[objective_4]], ".")) -> -6 | L6: =VALUE(_xlfn.TEXTBEFORE(evaluation_run_0__43[[#This Row],[objective_5]], ".")) -> -21 | M6: =VALUE(_xlfn.TEXTBEFORE(evaluation_run_0__43[[#This Row],[constraint]], ".")) -> 10 | P6: =MIN(I6,P5) -> 0 | Q6: =MIN(J6,Q5) -> 10 | R6: =MIN(K6,R5) -> -14 | S6: =MIN(L6+22,S5) -> 1 | T6: =MIN(M6,T5) -> 8 | V6: =evaluation_run_0__43[[#This Row],[elapsed_nanos]]/10^9 -> 0.0096 | W6: =IF(P$34=0,0,P38/P$34) -> 0 | X6: =IF(Q$34=0,0,Q38/Q$34) -> 0.22727273 | Y6: =IF(R$34=0,0,R38/R$34) -> 0.86842105 | Z6: =IF(S$34=0,0,S38/S$34) -> 0.5 | AA6: =IF(T$34=0,0,T38/T$34) -> 0.88888889
A7: 19858900 | B7: 0.0 | C7: 48.0 | D7: -16.0 | E7: -19.0 | F7: 8.0 | H7: =evaluation_run_0__43[[#This Row],[elapsed_nanos]]/10^9 -> 0.0198589 | I7: =VALUE(_xlfn.TEXTBEFORE(evaluation_run_0__43[[#This Row],[objective_0]], ".")) -> 0 | J7: =VALUE(_xlfn.TEXTBEFORE(evaluation_run_0__43[[#This Row],[objective_1]], ".")) -> 48 | K7: =VALUE(_xlfn.TEXTBEFORE(evaluation_run_0__43[[#This Row],[objective_4]], ".")) -> -16 | L7: =VALUE(_xlfn.TEXTBEFORE(evaluation_run_0__43[[#This Row],[objective_5]], ".")) -> -19 | M7: =VALUE(_xlfn.TEXTBEFORE(evaluation_run_0__43[[#This Row],[constraint]], ".")) -> 8 | P7: =MIN(I7,P6) -> 0 | Q7: =MIN(J7,Q6) -> 10 | R7: =MIN(K7,R6) -> -16 | S7: =MIN(L7+22,S6) -> 1 | T7: =MIN(M7,T6) -> 8 | V7: =evaluation_run_0__43[[#This Row],[elapsed_nanos]]/10^9 -> 0.0198589 | W7: =IF(P$34=0,0,P39/P$34) -> 0 | X7: =IF(Q$34=0,0,Q39/Q$34) -> 0.22727273 | Y7: =IF(R$34=0,0,R39/R$34) -> 0.81578947 | Z7: =IF(S$34=0,0,S39/S$34) -> 0.5 | AA7: =IF(T$34=0,0,T39/T$34) -> 0.88888889
A8: 23013600 | B8: 0.0 | C8: 44.0 | D8: -18.0 | E8: -19.0 | F8: 8.0 | H8: =evaluation_run_0__43[[#This Row],[elapsed_nanos]]/10^9 -> 0.0230136 | I8: =VALUE(_xlfn.TEXTBEFORE(evaluation_run_0__43[[#This Row],[objective_0]], ".")) -> 0 | J8: =VALUE(_xlfn.TEXTBEFORE(evaluation_run_0__43[[#This Row],[objective_1]], ".")) -> 44 | K8: =VALUE(_xlfn.TEXTBEFORE(evaluation_run_0__43[[#This Row],[objective_4]], ".")) -> -18 | L8: =VALUE(_xlfn.TEXTBEFORE(evaluation_run_0__43[[#This Row],[objective_5]], ".")) -> -19 | M8: =VALUE(_xlfn.TEXTBEFORE(evaluation_run_0__43[[#This Row],[constraint]], ".")) -> 8 | P8: =MIN(I8,P7) -> 0 | Q8: =MIN(J8,Q7) -> 10 | R8: =MIN(K8,R7) -> -18 | S8: =MIN(L8+22,S7) -> 1 | T8: =MIN(M8,T7) -> 8 | V8: =evaluation_run_0__43[[#This Row],[elapsed_nanos]]/10^9 -> 0.0230136 | W8: =IF(P$34=0,0,P40/P$34) -> 0 | X8: =IF(Q$34=0,0,Q40/Q$34) -> 0.22727273 | Y8: =IF(R$34=0,0,R40/R$34) -> 0.76315789 | Z8: =IF(S$34=0,0,S40/S$34) -> 0.5 | AA8: =IF(T$34=0,0,T40/T$34) -> 0.88888889
A9: 23755399 | B9: 0.0 | C9: 46.0 | D9: -19.0 | E9: -19.0 | F9: 8.0 | H9: =evaluation_run_0__43[[#This Row],[elapsed_nanos]]/10^9 -> 0.023755399 | I9: =VALUE(_xlfn.TEXTBEFORE(evaluation_run_0__43[[#This Row],[objective_0]], ".")) -> 0 | J9: =VALUE(_xlfn.TEXTBEFORE(evaluation_run_0__43[[#This Row],[objective_1]], ".")) -> 46 | K9: =VALUE(_xlfn.TEXTBEFORE(evaluation_run_0__43[[#This Row],[objective_4]], ".")) -> -19 | L9: =VALUE(_xlfn.TEXTBEFORE(evaluation_run_0__43[[#This Row],[objective_5]], ".")) -> -19 | M9: =VALUE(_xlfn.TEXTBEFORE(evaluation_run_0__43[[#This Row],[constraint]], ".")) -> 8 | P9: =MIN(I9,P8) -> 0 | Q9: =MIN(J9,Q8) -> 10 | R9: =MIN(K9,R8) -> -19 | S9: =MIN(L9+22,S8) -> 1 | T9: =MIN(M9,T8) -> 8 | V9: =evaluation_run_0__43[[#This Row],[elapsed_nanos]]/10^9 -> 0.023755399 | W9: =IF(P$34=0,0,P41/P$34) -> 0 | X9: =IF(Q$34=0,0,Q41/Q$34) -> 0.22727273 | Y9: =IF(R$34=0,0,R41/R$34) -> 0.73684211 | Z9: =IF(S$34=0,0,S41/S$34) -> 0.5 | AA9: =IF(T$34=0,0,T41/T$34) -> 0.88888889
A10: 27447600 | B10: 0.0 | C10: 40.0 | D10: -26.0 | E10: -19.0 | F10: 8.0 | H10: =evaluation_run_0__43[[#This Row],[elapsed_nanos]]/10^9 -> 0.0274476 | I10: =VALUE(_xlfn.TEXTBEFORE(evaluation_run_0__43[[#This Row],[objective_0]], ".")) -> 0 | J10: =VALUE(_xlfn.TEXTBEFORE(evaluation_run_0__43[[#This Row],[objective_1]], ".")) -> 40 | K10: =VALUE(_xlfn.TEXTBEFORE(evaluation_run_0__43[[#This Row],[objective_4]], ".")) -> -26 | L10: =VALUE(_xlfn.TEXTBEFORE(evaluation_run_0__43[[#This Row],[objective_5]], ".")) -> -19 | M10: =VALUE(_xlfn.TEXTBEFORE(evaluation_run_0__43[[#This Row],[constraint]], ".")) -> 8 | P10: =MIN(I10,P9) -> 0 | Q10: =MIN(J10,Q9) -> 10 | R10: =MIN(K10,R9) -> -26 | S10: =MIN(L10+22,S9) -> 1 | T10: =MIN(M10,T9) -> 8 | V10: =evaluation_run_0__43[[#This Row],[elapsed_nanos]]/10^9 -> 0.0274476 | W10: =IF(P$34=0,0,P42/P$34) -> 0 | X10: =IF(Q$34=0,0,Q42/Q$34) -> 0.22727273 | Y10: =IF(R$34=0,0,R42/R$34) -> 0.55263158 | Z10: =IF(S$34=0,0,S42/S$34) -> 0.5 | AA10: =IF(T$34=0,0,T42/T$34) -> 0.88888889
A11: 67712199 | B11: 9.0 | C11: 8.0 | D11: -6.0 | E11: -21.0 | F11: 10.0 | H11: =evaluation_run_0__43[[#This Row],[elapsed_nanos]]/10^9 -> 0.067712199 | I11: =VALUE(_xlfn.TEXTBEFORE(evaluation_run_0__43[[#This Row],[objective_0]], ".")) -> 9 | J11: =VALUE(_xlfn.TEXTBEFORE(evaluation_run_0__43[[#This Row],[objective_1]], ".")) -> 8 | K11: =VALUE(_xlfn.TEXTBEFORE(evaluation_run_0__43[[#This Row],[objective_4]], ".")) -> -6 | L11: =VALUE(_xlfn.TEXTBEFORE(evaluation_run_0__43[[#This Row],[objective_5]], ".")) -> -21 | M11: =VALUE(_xlfn.TEXTBEFORE(evaluation_run_0__43[[#This Row],[constraint]], ".")) -> 10 | P11: =MIN(I11,P10) -> 0 | Q11: =MIN(J11,Q10) -> 8 | R11: =MIN(K11,R10) -> -26 | S11: =MIN(L11+22,S10) -> 1 | T11: =MIN(M11,T10) -> 8 | V11: =evaluation_run_0__43[[#This Row],[elapsed_nanos]]/10^9 -> 0.067712199 | W11: =IF(P$34=0,0,P43/P$34) -> 0 | X11: =IF(Q$34=0,0,Q43/Q$34) -> 0.18181818 | Y11: =IF(R$34=0,0,R43/R$34) -> 0.55263158 | Z11: =IF(S$34=0,0,S43/S$34) -> 0.5 | AA11: =IF(T$34=0,0,T43/T$34) -> 0.88888889
A12: 200667400 | B12: 0.0 | C12: 72.0 | D12: -12.0 | E12: -19.0 | F12: 7.0 | H12: =evaluation_run_0__43[[#This Row],[elapsed_nanos]]/10^9 -> 0.2006674 | I12: =VALUE(_xlfn.TEXTBEFORE(evaluation_run_0__43[[#This Row],[objective_0]], ".")) -> 0 | J12: =VALUE(_xlfn.TEXTBEFORE(evaluation_run_0__43[[#This Row],[objective_1]], ".")) -> 72 | K12: =VALUE(_xlfn.TEXTBEFORE(evaluation_run_0__43[[#This Row],[objective_4]], ".")) -> -12 | L12: =VALUE(_xlfn.TEXTBEFORE(evaluation_run_0__43[[#This Row],[objective_5]], ".")) -> -19 | M12: =VALUE(_xlfn.TEXTBEFORE(evaluation_run_0__43[[#This Row],[constraint]], ".")) -> 7 | P12: =MIN(I12,P11) -> 0 | Q12: =MIN(J12,Q11) -> 8 | R12: =MIN(K12,R11) -> -26 | S12: =MIN(L12+22,S11) -> 1 | T12: =MIN(M12,T11) -> 7 | V12: =evaluation_run_0__43[[#This Row],[elapsed_nanos]]/10^9 -> 0.2006674 | W12: =IF(P$34=0,0,P44/P$34) -> 0 | X12: =IF(Q$34=0,0,Q44/Q$34) -> 0.18181818 | Y12: =IF(R$34=0,0,R44/R$34) -> 0.55263158 | Z12: =IF(S$34=0,0,S44/S$34) -> 0.5 | AA12: =IF(T$34=0,0,T44/T$34) -> 0.77777778
A13: 203221000 | B13: 0.0 | C13: 48.0 | D13: -31.0 | E13: -19.0 | F13: 7.0 | H13: =evaluation_run_0__43[[#This Row],[elapsed_nanos]]/10^9 -> 0.203221 | I13: =VALUE(_xlfn.TEXTBEFORE(evaluation_run_0__43[[#This Row],[objective_0]], ".")) -> 0 | J13: =VALUE(_xlfn.TEXTBEFORE(evaluation_run_0__43[[#This Row],[objective_1]], ".")) -> 48 | K13: =VALUE(_xlfn.TEXTBEFORE(evaluation_run_0__43[[#This Row],[objective_4]], ".")) -> -31 | L13: =VALUE(_xlfn.TEXTBEFORE(evaluation_run_0__43[[#This Row],[objective_5]], ".")) -> -19 | M13: =VALUE(_xlfn.TEXTBEFORE(evaluation_run_0__43[[#This Row],[constraint]], ".")) -> 7 | P13: =MIN(I13,P12) -> 0 | Q13: =MIN(J13,Q12) -> 8 | R13: =MIN(K13,R12) -> -31 | S13: =MIN(L13+22,S12) -> 1 | T13: =MIN(M13,T12) -> 7 | V13: =evaluation_run_0__43[[#This Row],[elapsed_nanos]]/10^9 -> 0.203221 | W13: =IF(P$34=0,0,P45/P$34) -> 0 | X13: =IF(Q$34=0,0,Q45/Q$34) -> 0.18181818 | Y13: =IF(R$34=0,0,R45/R$34) -> 0.42105263 | Z13: =IF(S$34=0,0,S45/S$34) -> 0.5 | AA13: =IF(T$34=0,0,T45/T$34) -> 0.77777778
A14: 238473800 | B14: 0.0 | C14: 24.0 | D14: -16.0 | E14: -22.0 | F14: 10.0 | H14: =evaluation_run_0__43[[#This Row],[elapsed_nanos]]/10^9 -> 0.2384738 | I14: =VALUE(_xlfn.TEXTBEFORE(evaluation_run_0__43[[#This Row],[objective_0]], ".")) -> 0 | J14: =VALUE(_xlfn.TEXTBEFORE(evaluation_run_0__43[[#This Row],[objective_1]], ".")) -> 24 | K14: =VALUE(_xlfn.TEXTBEFORE(evaluation_run_0__43[[#This Row],[objective_4]], ".")) -> -16 | L14: =VALUE(_xlfn.TEXTBEFORE(evaluation_run_0__43[[#This Row],[objective_5]], ".")) -> -22 | M14: =VALUE(_xlfn.TEXTBEFORE(evaluation_run_0__43[[#This Row],[constraint]], ".")) -> 10 | P14: =MIN(I14,P13) -> 0 | Q14: =MIN(J14,Q13) -> 8 | R14: =MIN(K14,R13) -> -31 | S14: =MIN(L14+22,S13) -> 0 | T14: =MIN(M14,T13) -> 7 | V14: =evaluation_run_0__43[[#This Row],[elapsed_nanos]]/10^9 -> 0.2384738 | W14: =IF(P$34=0,0,P46/P$34) -> 0 | X14: =IF(Q$34=0,0,Q46/Q$34) -> 0.18181818 | Y14: =IF(R$34=0,0,R46/R$34) -> 0.42105263 | Z14: =IF(S$34=0,0,S46/S$34) -> 0 | AA14: =IF(T$34=0,0,T46/T$34) -> 0.77777778
... A30: 41787024200 | B30: 9.0 | C30: 2.0 | D30: -14.0 | E30: -22.0 | F30: 8.0 | H30: =evaluation_run_0__43[[#This Row],[elapsed_nanos]]/10^9 -> 41.787024 | I30: =VALUE(_xlfn.TEXTBEFORE(evaluation_run_0__43[[#This Row],[objective_0]], ".")) -> 9 | J30: =VALUE(_xlfn.TEXTBEFORE(evaluation_run_0__43[[#This Row],[objective_1]], ".")) -> 2 | K30: =VALUE(_xlfn.TEXTBEFORE(evaluation_run_0__43[[#This Row],[objective_4]], ".")) -> -14 | L30: =VALUE(_xlfn.TEXTBEFORE(evaluation_run_0__43[[#This Row],[objective_5]], ".")) -> -22 | M30: =VALUE(_xlfn.TEXTBEFORE(evaluation_run_0__43[[#This Row],[constraint]], ".")) -> 8 | P30: =MIN(I30,P29) -> 0 | Q30: =MIN(J30,Q29) -> 2 | R30: =MIN(K30,R29) -> -47 | S30: =MIN(L30+22,S29) -> 0 | T30: =MIN(M30,T29) -> 0 | V30: =evaluation_run_0__43[[#This Row],[elapsed_nanos]]/10^9 -> 41.787024 | W30: =IF(P$34=0,0,P62/P$34) -> 0 | X30: =IF(Q$34=0,0,Q62/Q$34) -> 0.045454545 | Y30: =IF(R$34=0,0,R62/R$34) -> 0 | Z30: =IF(S$34=0,0,S62/S$34) -> 0 | AA30: =IF(T$34=0,0,T62/T$34) -> 0
P34: =IF(MIN(P$2:P$30)<0,P2-MIN(P$2:P$30),P2) -> 0 | Q34: =IF(MIN(Q$2:Q$30)<0,Q2-MIN(Q$2:Q$30),Q2) -> 44 | R34: =IF(MIN(R$2:R$30)<0,R2-MIN(R$2:R$30),R2) -> 38 | S34: =IF(MIN(S$2:S$30)<0,S2-MIN(S$2:S$30),S2) -> 2 | T34: =IF(MIN(T$2:T$30)<0,T2-MIN(T$2:T$30),T2) -> 9
P35: =IF(MIN(P$2:P$30)<0,P3-MIN(P$2:P$30),P3) -> 0 | Q35: =IF(MIN(Q$2:Q$30)<0,Q3-MIN(Q$2:Q$30),Q3) -> 44 | R35: =IF(MIN(R$2:R$30)<0,R3-MIN(R$2:R$30),R3) -> 33 | S35: =IF(MIN(S$2:S$30)<0,S3-MIN(S$2:S$30),S3) -> 2 | T35: =IF(MIN(T$2:T$30)<0,T3-MIN(T$2:T$30),T3) -> 8
P36: =IF(MIN(P$2:P$30)<0,P4-MIN(P$2:P$30),P4) -> 0 | Q36: =IF(MIN(Q$2:Q$30)<0,Q4-MIN(Q$2:Q$30),Q4) -> 24 | R36: =IF(MIN(R$2:R$30)<0,R4-MIN(R$2:R$30),R4) -> 33 | S36: =IF(MIN(S$2:S$30)<0,S4-MIN(S$2:S$30),S4) -> 2 | T36: =IF(MIN(T$2:T$30)<0,T4-MIN(T$2:T$30),T4) -> 8
P37: =IF(MIN(P$2:P$30)<0,P5-MIN(P$2:P$30),P5) -> 0 | Q37: =IF(MIN(Q$2:Q$30)<0,Q5-MIN(Q$2:Q$30),Q5) -> 12 | R37: =IF(MIN(R$2:R$30)<0,R5-MIN(R$2:R$30),R5) -> 33 | S37: =IF(MIN(S$2:S$30)<0,S5-MIN(S$2:S$30),S5) -> 1 | T37: =IF(MIN(T$2:T$30)<0,T5-MIN(T$2:T$30),T5) -> 8
P38: =IF(MIN(P$2:P$30)<0,P6-MIN(P$2:P$30),P6) -> 0 | Q38: =IF(MIN(Q$2:Q$30)<0,Q6-MIN(Q$2:Q$30),Q6) -> 10 | R38: =IF(MIN(R$2:R$30)<0,R6-MIN(R$2:R$30),R6) -> 33 | S38: =IF(MIN(S$2:S$30)<0,S6-MIN(S$2:S$30),S6) -> 1 | T38: =IF(MIN(T$2:T$30)<0,T6-MIN(T$2:T$30),T6) -> 8
P39: =IF(MIN(P$2:P$30)<0,P7-MIN(P$2:P$30),P7) -> 0 | Q39: =IF(MIN(Q$2:Q$30)<0,Q7-MIN(Q$2:Q$30),Q7) -> 10 | R39: =IF(MIN(R$2:R$30)<0,R7-MIN(R$2:R$30),R7) -> 31 | S39: =IF(MIN(S$2:S$30)<0,S7-MIN(S$2:S$30),S7) -> 1 | T39: =IF(MIN(T$2:T$30)<0,T7-MIN(T$2:T$30),T7) -> 8
P40: =IF(MIN(P$2:P$30)<0,P8-MIN(P$2:P$30),P8) -> 0 | Q40: =IF(MIN(Q$2:Q$30)<0,Q8-MIN(Q$2:Q$30),Q8) -> 10 | R40: =IF(MIN(R$2:R$30)<0,R8-MIN(R$2:R$30),R8) -> 29 | S40: =IF(MIN(S$2:S$30)<0,S8-MIN(S$2:S$30),S8) -> 1 | T40: =IF(MIN(T$2:T$30)<0,T8-MIN(T$2:T$30),T8) -> 8
P41: =IF(MIN(P$2:P$30)<0,P9-MIN(P$2:P$30),P9) -> 0 | Q41: =IF(MIN(Q$2:Q$30)<0,Q9-MIN(Q$2:Q$30),Q9) -> 10 | R41: =IF(MIN(R$2:R$30)<0,R9-MIN(R$2:R$30),R9) -> 28 | S41: =IF(MIN(S$2:S$30)<0,S9-MIN(S$2:S$30),S9) -> 1 | T41: =IF(MIN(T$2:T$30)<0,T9-MIN(T$2:T$30),T9) -> 8
P42: =IF(MIN(P$2:P$30)<0,P10-MIN(P$2:P$30),P10) -> 0 | Q42: =IF(MIN(Q$2:Q$30)<0,Q10-MIN(Q$2:Q$30),Q10) -> 10 | R42: =IF(MIN(R$2:R$30)<0,R10-MIN(R$2:R$30),R10) -> 21 | S42: =IF(MIN(S$2:S$30)<0,S10-MIN(S$2:S$30),S10) -> 1 | T42: =IF(MIN(T$2:T$30)<0,T10-MIN(T$2:T$30),T10) -> 8
P43: =IF(MIN(P$2:P$30)<0,P11-MIN(P$2:P$30),P11) -> 0 | Q43: =IF(MIN(Q$2:Q$30)<0,Q11-MIN(Q$2:Q$30),Q11) -> 8 | R43: =IF(MIN(R$2:R$30)<0,R11-MIN(R$2:R$30),R11) -> 21 | S43: =IF(MIN(S$2:S$30)<0,S11-MIN(S$2:S$30),S11) -> 1 | T43: =IF(MIN(T$2:T$30)<0,T11-MIN(T$2:T$30),T11) -> 8
P44: =IF(MIN(P$2:P$30)<0,P12-MIN(P$2:P$30),P12) -> 0 | Q44: =IF(MIN(Q$2:Q$30)<0,Q12-MIN(Q$2:Q$30),Q12) -> 8 | R44: =IF(MIN(R$2:R$30)<0,R12-MIN(R$2:R$30),R12) -> 21 | S44: =IF(MIN(S$2:S$30)<0,S12-MIN(S$2:S$30),S12) -> 1 | T44: =IF(MIN(T$2:T$30)<0,T12-MIN(T$2:T$30),T12) -> 7
P45: =IF(MIN(P$2:P$30)<0,P13-MIN(P$2:P$30),P13) -> 0 | Q45: =IF(MIN(Q$2:Q$30)<0,Q13-MIN(Q$2:Q$30),Q13) -> 8 | R45: =IF(MIN(R$2:R$30)<0,R13-MIN(R$2:R$30),R13) -> 16 | S45: =IF(MIN(S$2:S$30)<0,S13-MIN(S$2:S$30),S13) -> 1 | T45: =IF(MIN(T$2:T$30)<0,T13-MIN(T$2:T$30),T13) -> 7
... P62: =IF(MIN(P$2:P$30)<0,P30-MIN(P$2:P$30),P30) -> 0 | Q62: =IF(MIN(Q$2:Q$30)<0,Q30-MIN(Q$2:Q$30),Q30) -> 2 | R62: =IF(MIN(R$2:R$30)<0,R30-MIN(R$2:R$30),R30) -> 0 | S62: =IF(MIN(S$2:S$30)<0,S30-MIN(S$2:S$30),S30) -> 0 | T62: =IF(MIN(T$2:T$30)<0,T30-MIN(T$2:T$30),T30) -> 0

Sheet variation_metrics
A4: SOC MIN | M4: SOC MIN
A5: crossover_nanos | B5: mutation_nanos | C5: eval_measurement_nanos | D5: total_cross | E5: success_cross | F5: total_mut | G5: success_mut | H5: total_eval | I5: success_eval | J5: total_nanos | M5: total_nanos | N5: crossover_nanos | O5: mutation_nanos | P5: eval_measurement_nanos | Q5: total_cross | R5: success_cross | S5: total_mut | T5: success_mut | U5: total_eval | V5: success_eval
A6: 715095500 | B6: 5050724900 | C6: 775500 | D6: 149 | E6: 101 | F6: 3817 | G6: 3817 | H6: 2917 | I6: 2917 | J6: 10000000000 | M6: =MEDIAN(variation_metrics__2[total_nanos]) -> 10000000000 | N6: =MEDIAN(variation_metrics__2[crossover_nanos]) -> 715095500 | O6: =MEDIAN(variation_metrics__2[mutation_nanos]) -> 5169529600 | P6: =MEDIAN(variation_metrics__2[eval_measurement_nanos]) -> 553300 | Q6: =MEDIAN(variation_metrics__2[total_cross]) -> 173 | R6: =MEDIAN(variation_metrics__2[success_cross]) -> 121 | S6: =MEDIAN(variation_metrics__2[total_mut]) -> 4417 | T6: =MEDIAN(variation_metrics__2[success_mut]) -> 4416 | U6: =MEDIAN(variation_metrics__2[total_eval]) -> 3517 | V6: =MEDIAN(variation_metrics__2[success_eval]) -> 3516
A7: 743506100 | B7: 5166228800 | C7: 493400 | D7: 164 | E7: 102 | F7: 4114 | G7: 4114 | H7: 3214 | I7: 3214 | J7: 10000000000 | L7: in sec | M7: =M6/10^9 -> 10 | N7: =N6/10^9 -> 0.7150955 | O7: =O6/10^9 -> 5.1695296 | P7: =P6/10^9 -> 0.0005533
A8: 665737400 | B8: 5197130600 | C8: 554400 | D8: 183 | E8: 124 | F8: 4816 | G8: 4816 | H8: 3916 | I8: 3916 | J8: 10000000000 | Q8: rate | R8: =R6/Q6 -> 0.69942197 | S8: rate | T8: =T6/S6 -> 0.9997736 | U8: rate | V8: =V6/U6 -> 0.99971567
A9: 634566000 | B9: 5255410400 | C9: 628000 | D9: 203 | E9: 142 | F9: 5122 | G9: 5122 | H9: 4222 | I9: 4222 | J9: 10000000000
A10: 719666500 | B10: 5124017400 | C10: 586100 | D10: 213 | E10: 138 | F10: 5016 | G10: 5016 | H10: 4116 | I10: 4116 | J10: 10000000000
A11: 622163900 | B11: 5255661100 | C11: 550700 | D11: 164 | E11: 121 | F11: 4417 | G11: 4416 | H11: 3517 | I11: 3516 | J11: 10000000000
A12: 747415000 | B12: 5140545100 | C12: 553300 | D12: 209 | E12: 141 | F12: 4721 | G12: 4721 | H12: 3821 | I12: 3821 | J12: 10000000000
A13: 721243400 | B13: 5210194200 | C13: 508500 | D13: 173 | E13: 96 | F13: 4214 | G13: 4214 | H13: 3314 | I13: 3314 | J13: 10000000000
A14: 697160500 | B14: 5169529600 | C14: 479600 | D14: 158 | E14: 95 | F14: 4115 | G14: 4115 | H14: 3215 | I14: 3215 | J14: 10000000000
A16: SOC MAX | M16: SOC MAX
A17: crossover_nanos | B17: mutation_nanos | C17: eval_measurement_nanos | D17: total_cross | E17: success_cross | F17: total_mut | G17: success_mut | H17: total_eval | I17: success_eval | J17: total_nanos | M17: total_nanos | N17: crossover_nanos | O17: mutation_nanos | P17: eval_measurement_nanos | Q17: total_cross | R17: success_cross | S17: total_mut | T17: success_mut | U17: total_eval | V17: success_eval
A18: 749252600 | B18: 5032092700 | C18: 835800 | D18: 166 | E18: 120 | F18: 4018 | G18: 4018 | H18: 3118 | I18: 3118 | J18: 10000000000 | M18: =MEDIAN(variation_metrics__312[total_nanos]) -> 10000000000 | N18: =MEDIAN(variation_metrics__312[crossover_nanos]) -> 714693700 | O18: =MEDIAN(variation_metrics__312[mutation_nanos]) -> 5180920600 | P18: =MEDIAN(variation_metrics__312[eval_measurement_nanos]) -> 502800 | Q18: =MEDIAN(variation_metrics__312[total_cross]) -> 157 | R18: =MEDIAN(variation_metrics__312[success_cross]) -> 101 | S18: =MEDIAN(variation_metrics__312[total_mut]) -> 3913 | T18: =MEDIAN(variation_metrics__312[success_mut]) -> 3912 | U18: =MEDIAN(variation_metrics__312[total_eval]) -> 3013 | V18: =MEDIAN(variation_metrics__312[success_eval]) -> 3012
A19: 828357600 | B19: 4998356300 | C19: 425800 | D19: 169 | E19: 107 | F19: 3913 | G19: 3910 | H19: 3013 | I19: 3010 | J19: 10000000000 | L19: in sec | M19: =M18/10^9 -> 10 | N19: =N18/10^9 -> 0.7146937 | O19: =O18/10^9 -> 5.1809206 | P19: =P18/10^9 -> 0.0005028
A20: 689095900 | B20: 5183924800 | C20: 545500 | D20: 159 | E20: 94 | F20: 4118 | G20: 4116 | H20: 3218 | I20: 3216 | J20: 10000000000 | Q20: rate | R20: =R18/Q18 -> 0.6433121 | S20: rate | T20: =T18/S18 -> 0.99974444 | U20: rate | V20: =V18/U18 -> 0.9996681
A21: 766913000 | B21: 5227329900 | C21: 456700 | D21: 155 | E21: 118 | F21: 3910 | G21: 3908 | H21: 3010 | I21: 3008 | J21: 10000000000
A22: 707186100 | B22: 5215800100 | C22: 593100 | D22: 124 | E22: 73 | F22: 3509 | G22: 3509 | H22: 2609 | I22: 2607 | J22: 10000000000
A23: 714693700 | B23: 5180920600 | C23: 502800 | D23: 151 | E23: 101 | F23: 3915 | G23: 3910 | H23: 3015 | I23: 3010 | J23: 10000000000
A24: 653615800 | B24: 5251469700 | C24: 483000 | D24: 135 | E24: 80 | F24: 3912 | G24: 3912 | H24: 3012 | I24: 3012 | J24: 10000000000
A25: 786966100 | B25: 4960563200 | C25: 536400 | D25: 162 | E25: 93 | F25: 3913 | G25: 3912 | H25: 3013 | I25: 3012 | J25: 10000000000
A26: 707790200 | B26: 5037526500 | C26: 431700 | D26: 157 | E26: 114 | F26: 4114 | G26: 4112 | H26: 3214 | I26: 3212 | J26: 10000000000
A28: CRA | M28: CRA
A29: crossover_nanos | B29: mutation_nanos | C29: eval_measurement_nanos | D29: total_cross | E29: success_cross | F29: total_mut | G29: success_mut | H29: total_eval | I29: success_eval | J29: total_nanos | M29: total_nanos | N29: crossover_nanos | O29: mutation_nanos | P29: eval_measurement_nanos | Q29: total_cross | R29: success_cross | S29: total_mut | T29: success_mut | U29: total_eval | V29: success_eval
A30: 665445905 | B30: 4892613371 | C30: 1005624 | D30: 174 | E30: 84 | F30: 4622 | G30: 4622 | H30: 3722 | I30: 3717 | J30: 10000000000 | M30: =MEDIAN(variation_metrics[total_nanos]) -> 10000000000 | N30: =MEDIAN(variation_metrics[crossover_nanos]) -> 693413206 | O30: =MEDIAN(variation_metrics[mutation_nanos]) -> 4982288846 | P30: =MEDIAN(variation_metrics[eval_measurement_nanos]) -> 649964 | Q30: =MEDIAN(variation_metrics[total_cross]) -> 195 | R30: =MEDIAN(variation_metrics[success_cross]) -> 96 | S30: =MEDIAN(variation_metrics[total_mut]) -> 4920 | T30: =MEDIAN(variation_metrics[success_mut]) -> 4888 | U30: =MEDIAN(variation_metrics[total_eval]) -> 4020 | V30: =MEDIAN(variation_metrics[success_eval]) -> 3988
A31: 693413206 | B31: 5014895846 | C31: 728761 | D31: 208 | E31: 106 | F31: 5216 | G31: 5216 | H31: 4316 | I31: 4306 | J31: 10000000000 | L31: in sec | M31: =M30/10^9 -> 10 | N31: =N30/10^9 -> 0.69341321 | O31: =O30/10^9 -> 4.9822888 | P31: =P30/10^9 -> 0.000649964
A32: 757282190 | B32: 4932620990 | C32: 649964 | D32: 195 | E32: 81 | F32: 4723 | G32: 4721 | H32: 3823 | I32: 3818 | J32: 10000000000 | Q32: rate | R32: =R30/Q30 -> 0.49230769 | S32: rate | T32: =T30/S30 -> 0.99349593 | U32: rate | V32: =V30/U30 -> 0.9920398
A33: 662281195 | B33: 4987753490 | C33: 601682 | D33: 185 | E33: 99 | F33: 4921 | G33: 4888 | H33: 4021 | I33: 3988 | J33: 10000000000
A34: 662389458 | B34: 5094387813 | C34: 614057 | D34: 191 | E34: 96 | F34: 4920 | G34: 4920 | H34: 4020 | I34: 4016 | J34: 10000000000
A35: 733498999 | B35: 4888705886 | C35: 660314 | D35: 200 | E35: 86 | F35: 4816 | G35: 4816 | H35: 3916 | I35: 3914 | J35: 10000000000
A36: 724117315 | B36: 4982288846 | C36: 664411 | D36: 226 | E36: 124 | F36: 5328 | G36: 5306 | H36: 4428 | I36: 4401 | J36: 10000000000
A37: 739382420 | B37: 5026634776 | C37: 600263 | D37: 230 | E37: 99 | F37: 5421 | G37: 5263 | H37: 4521 | I37: 4362 | J37: 10000000000
A38: 669072978 | B38: 4968867904 | C38: 595110 | D38: 186 | E38: 77 | F38: 4819 | G38: 4819 | H38: 3919 | I38: 3913 | J38: 10000000000

Sheet pareto_cra
B1: version, | C1: Obj1, | D1: Obj2, | E1: Obj5, | F1: Obj6, | G1: Constr1
B2: tools.refinery.store.dse.evolutionary.VersionVariable@9ead27f4, | C2: 0,000000, | D2: 200,000000, | E2: -47,000000, | F2: -22,000000, | G2: 0
B3: tools.refinery.store.dse.evolutionary.VersionVariable@ea404534, | C3: 9,000000, | D3: 2,000000, | E3: -15,000000, | F3: -22,000000, | G3: 6
B4: tools.refinery.store.dse.evolutionary.VersionVariable@a5fad7f9, | C4: 7,000000, | D4: 2,000000, | E4: -17,000000, | F4: -22,000000, | G4: 7
B5: tools.refinery.store.dse.evolutionary.VersionVariable@f8c6167e, | C5: 0,000000, | D5: 4,000000, | E5: -21,000000, | F5: -22,000000, | G5: 7
B6: tools.refinery.store.dse.evolutionary.VersionVariable@f968a3ae, | C6: 16,000000, | D6: 10,000000, | E6: -31,000000, | F6: -22,000000, | G6: 0
B7: tools.refinery.store.dse.evolutionary.VersionVariable@8dc3ba92, | C7: 0,000000, | D7: 170,000000, | E7: -46,000000, | F7: -22,000000, | G7: 1
B8: tools.refinery.store.dse.evolutionary.VersionVariable@278b679, | C8: 1,000000, | D8: 118,000000, | E8: -46,000000, | F8: -22,000000, | G8: 0
B9: tools.refinery.store.dse.evolutionary.VersionVariable@b7995b53, | C9: 0,000000, | D9: 70,000000, | E9: -43,000000, | F9: -22,000000, | G9: 3
B10: tools.refinery.store.dse.evolutionary.VersionVariable@9667c13a, | C10: 0,000000, | D10: 92,000000, | E10: -44,000000, | F10: -22,000000, | G10: 2
B11: tools.refinery.store.dse.evolutionary.VersionVariable@b93d449a, | C11: 8,000000, | D11: 6,000000, | E11: -23,000000, | F11: -22,000000, | G11: 3
B12: tools.refinery.store.dse.evolutionary.VersionVariable@a23fd59f, | C12: 13,000000, | D12: 2,000000, | E12: -22,000000, | F12: -22,000000, | G12: 5
B13: tools.refinery.store.dse.evolutionary.VersionVariable@eab9b622, | C13: 15,000000, | D13: 6,000000, | E13: -30,000000, | F13: -22,000000, | G13: 2
... B93: tools.refinery.store.dse.evolutionary.VersionVariable@bc384546, | C93: 2,000000, | D93: 34,000000, | E93: -43,000000, | F93: -22,000000, | G93: 1
N94: interClassDependency | O94: inClassNoDependency | P94: inClassDependency
N95: 0 | O95: 200 | P95: -47
N96: 16 | O96: 10 | P96: -31
N97: 1 | O97: 118 | P97: -46
N98: 2 | O98: 54 | P98: -45
N99: 14 | O99: 14 | P99: -33
N100: 13 | O100: 16 | P100: -34
N101: 10 | O101: 18 | P101: -37
N102: 6 | O102: 26 | P102: -41
N103: 3 | O103: 36 | P103: -44
N104: 9 | O104: 22 | P104: -38
N105: 4 | O105: 34 | P105: -43
C109: S1 | D109: S2 | E109: S3 | F109: S4 | G109: S5 | H109: S6 | I109: S7 | J109: S8 | K109: S9 | L109: S10 | M109: S11
B110: interClassDependency | C110: 0 | D110: 1 | E110: 2 | F110: 3 | G110: 4 | H110: 6 | I110: 9 | J110: 10 | K110: 13 | L110: 14 | M110: 16
B111: inClassNoDependency | C111: 200 | D111: 118 | E111: 54 | F111: 36 | G111: 34 | H111: 26 | I111: 22 | J111: 18 | K111: 16 | L111: 14 | M111: 10
B112: inClassDependency | C112: -47 | D112: -46 | E112: -45 | F112: -44 | G112: -43 | H112: -41 | I112: -38 | J112: -37 | K112: -34 | L112: -33 | M112: -31

Sheet result_population_numbers
A1: =result_population!A1 -> SOC MIN | B1: =result_population!B1 -> ownerAndPetAreNotFriends | C1: =result_population!C1 -> notEnoughFriendsForPerson | D1: =result_population!D1 -> beingInFriendTriangle | E1: =result_population!E1 -> size | F1: =result_population!F1 -> personWithMoreThan2Dogs or dogWithoutOwner | I1: =result_population!I1 -> SOC_MAX | J1: =result_population!J1 -> ownerAndPetAreNotFriends | K1: =result_population!K1 -> notEnoughFriendsForPerson | L1: =result_population!L1 -> beingInFriendTriangle | M1: =result_population!M1 -> size | N1: =result_population!N1 -> personWithMoreThan2Dogs or dogWithoutOwner | Q1: =result_population!Q1 -> CRA | R1: =result_population!R1 -> interClassDependency | S1: =result_population!S1 -> inClassNoDependency | T1: =result_population!V1 -> inClassDependency | U1: =result_population!W1 -> size | V1: =result_population!X1 -> featureHasNoClass
A2: =result_population!A2 -> version, | B2: =result_population!B2 -> Obj1, | C2: =result_population!C2 -> Obj2, | D2: =result_population!D2 -> Obj3, | E2: =result_population!E2 -> Obj5, | F2: =result_population!F2 -> Constr1 | I2: =result_population!I2 -> version, | J2: =result_population!J2 -> Obj1, | K2: =result_population!K2 -> Obj2, | L2: =result_population!L2 -> Obj4, | M2: =result_population!M2 -> Obj5, | N2: =result_population!N2 -> Constr1 | Q2: =result_population!Q2 -> version, | R2: =result_population!R2 -> Obj1, | S2: =result_population!S2 -> Obj2, | T2: =result_population!V2 -> Obj5, | U2: =result_population!W2 -> Obj6, | V2: =result_population!X2 -> Constr1
B3: =VALUE(_xlfn.TEXTBEFORE(result_population!B3,",")) -> 0 | C3: =VALUE(_xlfn.TEXTBEFORE(result_population!C3,",")) -> 2 | D3: =VALUE(_xlfn.TEXTBEFORE(result_population!D3,",")) -> 0 | E3: =VALUE(_xlfn.TEXTBEFORE(result_population!E3,",")) -> -7 | F3: =result_population__614[[#This Row],[Constr1]] -> 1 | J3: =VALUE(_xlfn.TEXTBEFORE(result_population!J3,",")) -> 0 | K3: =VALUE(_xlfn.TEXTBEFORE(result_population!K3,",")) -> 1 | L3: =VALUE(_xlfn.TEXTBEFORE(result_population!L3,",")) -> -5 | M3: =VALUE(_xlfn.TEXTBEFORE(result_population!M3,",")) -> -8 | N3: =result_population__818[[#This Row],[Constr1]] -> 1 | R3: =VALUE(_xlfn.TEXTBEFORE(result_population!R3,",")) -> 0 | S3: =VALUE(_xlfn.TEXTBEFORE(result_population!S3,",")) -> 200 | T3: =VALUE(_xlfn.TEXTBEFORE(result_population!V3,",")) -> -47 | U3: =VALUE(_xlfn.TEXTBEFORE(result_population!W3,",")) -> -22 | V3: =result_population__411[[#This Row],[Constr1]] -> 0
B4: =VALUE(_xlfn.TEXTBEFORE(result_population!B4,",")) -> 0 | C4: =VALUE(_xlfn.TEXTBEFORE(result_population!C4,",")) -> 1 | D4: =VALUE(_xlfn.TEXTBEFORE(result_population!D4,",")) -> 0 | E4: =VALUE(_xlfn.TEXTBEFORE(result_population!E4,",")) -> -6 | F4: =result_population__614[[#This Row],[Constr1]] -> 1 | J4: =VALUE(_xlfn.TEXTBEFORE(result_population!J4,",")) -> 3 | K4: =VALUE(_xlfn.TEXTBEFORE(result_population!K4,",")) -> 2 | L4: =VALUE(_xlfn.TEXTBEFORE(result_population!L4,",")) -> -6 | M4: =VALUE(_xlfn.TEXTBEFORE(result_population!M4,",")) -> -12 | N4: =result_population__818[[#This Row],[Constr1]] -> 1 | R4: =VALUE(_xlfn.TEXTBEFORE(result_population!R4,",")) -> 9 | S4: =VALUE(_xlfn.TEXTBEFORE(result_population!S4,",")) -> 2 | T4: =VALUE(_xlfn.TEXTBEFORE(result_population!V4,",")) -> -15 | U4: =VALUE(_xlfn.TEXTBEFORE(result_population!W4,",")) -> -22 | V4: =result_population__411[[#This Row],[Constr1]] -> 6
B5: =VALUE(_xlfn.TEXTBEFORE(result_population!B5,",")) -> 4 | C5: =VALUE(_xlfn.TEXTBEFORE(result_population!C5,",")) -> 10 | D5: =VALUE(_xlfn.TEXTBEFORE(result_population!D5,",")) -> 0 | E5: =VALUE(_xlfn.TEXTBEFORE(result_population!E5,",")) -> -18 | F5: =result_population__614[[#This Row],[Constr1]] -> 1 | J5: =VALUE(_xlfn.TEXTBEFORE(result_population!J5,",")) -> 5 | K5: =VALUE(_xlfn.TEXTBEFORE(result_population!K5,",")) -> 9 | L5: =VALUE(_xlfn.TEXTBEFORE(result_population!L5,",")) -> 0 | M5: =VALUE(_xlfn.TEXTBEFORE(result_population!M5,",")) -> -20 | N5: =result_population__818[[#This Row],[Constr1]] -> 1 | R5: =VALUE(_xlfn.TEXTBEFORE(result_population!R5,",")) -> 7 | S5: =VALUE(_xlfn.TEXTBEFORE(result_population!S5,",")) -> 2 | T5: =VALUE(_xlfn.TEXTBEFORE(result_population!V5,",")) -> -17 | U5: =VALUE(_xlfn.TEXTBEFORE(result_population!W5,",")) -> -22 | V5: =result_population__411[[#This Row],[Constr1]] -> 7
B6: =VALUE(_xlfn.TEXTBEFORE(result_population!B6,",")) -> 0 | C6: =VALUE(_xlfn.TEXTBEFORE(result_population!C6,",")) -> 1 | D6: =VALUE(_xlfn.TEXTBEFORE(result_population!D6,",")) -> 0 | E6: =VALUE(_xlfn.TEXTBEFORE(result_population!E6,",")) -> -13 | F6: =result_population__614[[#This Row],[Constr1]] -> 8 | J6: =VALUE(_xlfn.TEXTBEFORE(result_population!J6,",")) -> 1 | K6: =VALUE(_xlfn.TEXTBEFORE(result_population!K6,",")) -> 3 | L6: =VALUE(_xlfn.TEXTBEFORE(result_population!L6,",")) -> 0 | M6: =VALUE(_xlfn.TEXTBEFORE(result_population!M6,",")) -> -15 | N6: =result_population__818[[#This Row],[Constr1]] -> 4 | R6: =VALUE(_xlfn.TEXTBEFORE(result_population!R6,",")) -> 0 | S6: =VALUE(_xlfn.TEXTBEFORE(result_population!S6,",")) -> 4 | T6: =VALUE(_xlfn.TEXTBEFORE(result_population!V6,",")) -> -21 | U6: =VALUE(_xlfn.TEXTBEFORE(result_population!W6,",")) -> -22 | V6: =result_population__411[[#This Row],[Constr1]] -> 7
B7: =VALUE(_xlfn.TEXTBEFORE(result_population!B7,",")) -> 3 | C7: =VALUE(_xlfn.TEXTBEFORE(result_population!C7,",")) -> 9 | D7: =VALUE(_xlfn.TEXTBEFORE(result_population!D7,",")) -> 3 | E7: =VALUE(_xlfn.TEXTBEFORE(result_population!E7,",")) -> -18 | F7: =result_population__614[[#This Row],[Constr1]] -> 1 | J7: =VALUE(_xlfn.TEXTBEFORE(result_population!J7,",")) -> 0 | K7: =VALUE(_xlfn.TEXTBEFORE(result_population!K7,",")) -> 2 | L7: =VALUE(_xlfn.TEXTBEFORE(result_population!L7,",")) -> -4 | M7: =VALUE(_xlfn.TEXTBEFORE(result_population!M7,",")) -> -14 | N7: =result_population__818[[#This Row],[Constr1]] -> 8 | R7: =VALUE(_xlfn.TEXTBEFORE(result_population!R7,",")) -> 16 | S7: =VALUE(_xlfn.TEXTBEFORE(result_population!S7,",")) -> 10 | T7: =VALUE(_xlfn.TEXTBEFORE(result_population!V7,",")) -> -31 | U7: =VALUE(_xlfn.TEXTBEFORE(result_population!W7,",")) -> -22 | V7: =result_population__411[[#This Row],[Constr1]] -> 0
B8: =VALUE(_xlfn.TEXTBEFORE(result_population!B8,",")) -> 8 | C8: =VALUE(_xlfn.TEXTBEFORE(result_population!C8,",")) -> 6 | D8: =VALUE(_xlfn.TEXTBEFORE(result_population!D8,",")) -> 0 | E8: =VALUE(_xlfn.TEXTBEFORE(result_population!E8,",")) -> -18 | F8: =result_population__614[[#This Row],[Constr1]] -> 2 | J8: =VALUE(_xlfn.TEXTBEFORE(result_population!J8,",")) -> 5 | K8: =VALUE(_xlfn.TEXTBEFORE(result_population!K8,",")) -> 2 | L8: =VALUE(_xlfn.TEXTBEFORE(result_population!L8,",")) -> -5 | M8: =VALUE(_xlfn.TEXTBEFORE(result_population!M8,",")) -> -14 | N8: =result_population__818[[#This Row],[Constr1]] -> 2 | R8: =VALUE(_xlfn.TEXTBEFORE(result_population!R8,",")) -> 0 | S8: =VALUE(_xlfn.TEXTBEFORE(result_population!S8,",")) -> 170 | T8: =VALUE(_xlfn.TEXTBEFORE(result_population!V8,",")) -> -46 | U8: =VALUE(_xlfn.TEXTBEFORE(result_population!W8,",")) -> -22 | V8: =result_population__411[[#This Row],[Constr1]] -> 1
B9: =VALUE(_xlfn.TEXTBEFORE(result_population!B9,",")) -> 1 | C9: =VALUE(_xlfn.TEXTBEFORE(result_population!C9,",")) -> 1 | D9: =VALUE(_xlfn.TEXTBEFORE(result_population!D9,",")) -> 3 | E9: =VALUE(_xlfn.TEXTBEFORE(result_population!E9,",")) -> -8 | F9: =result_population__614[[#This Row],[Constr1]] -> 1 | J9: =VALUE(_xlfn.TEXTBEFORE(result_population!J9,",")) -> 1 | K9: =VALUE(_xlfn.TEXTBEFORE(result_population!K9,",")) -> 4 | L9: =VALUE(_xlfn.TEXTBEFORE(result_population!L9,",")) -> -3 | M9: =VALUE(_xlfn.TEXTBEFORE(result_population!M9,",")) -> -16 | N9: =result_population__818[[#This Row],[Constr1]] -> 5 | R9: =VALUE(_xlfn.TEXTBEFORE(result_population!R9,",")) -> 1 | S9: =VALUE(_xlfn.TEXTBEFORE(result_population!S9,",")) -> 118 | T9: =VALUE(_xlfn.TEXTBEFORE(result_population!V9,",")) -> -46 | U9: =VALUE(_xlfn.TEXTBEFORE(result_population!W9,",")) -> -22 | V9: =result_population__411[[#This Row],[Constr1]] -> 0
B10: =VALUE(_xlfn.TEXTBEFORE(result_population!B10,",")) -> 2 | C10: =VALUE(_xlfn.TEXTBEFORE(result_population!C10,",")) -> 8 | D10: =VALUE(_xlfn.TEXTBEFORE(result_population!D10,",")) -> 3 | E10: =VALUE(_xlfn.TEXTBEFORE(result_population!E10,",")) -> -17 | F10: =result_population__614[[#This Row],[Constr1]] -> 2 | J10: =VALUE(_xlfn.TEXTBEFORE(result_population!J10,",")) -> 2 | K10: =VALUE(_xlfn.TEXTBEFORE(result_population!K10,",")) -> 5 | L10: =VALUE(_xlfn.TEXTBEFORE(result_population!L10,",")) -> -4 | M10: =VALUE(_xlfn.TEXTBEFORE(result_population!M10,",")) -> -17 | N10: =result_population__818[[#This Row],[Constr1]] -> 6 | R10: =VALUE(_xlfn.TEXTBEFORE(result_population!R10,",")) -> 0 | S10: =VALUE(_xlfn.TEXTBEFORE(result_population!S10,",")) -> 70 | T10: =VALUE(_xlfn.TEXTBEFORE(result_population!V10,",")) -> -43 | U10: =VALUE(_xlfn.TEXTBEFORE(result_population!W10,",")) -> -22 | V10: =result_population__411[[#This Row],[Constr1]] -> 3
B11: =VALUE(_xlfn.TEXTBEFORE(result_population!B11,",")) -> 2 | C11: =VALUE(_xlfn.TEXTBEFORE(result_population!C11,",")) -> 2 | D11: =VALUE(_xlfn.TEXTBEFORE(result_population!D11,",")) -> 3 | E11: =VALUE(_xlfn.TEXTBEFORE(result_population!E11,",")) -> -13 | F11: =result_population__614[[#This Row],[Constr1]] -> 4 | J11: =VALUE(_xlfn.TEXTBEFORE(result_population!J11,",")) -> 3 | K11: =VALUE(_xlfn.TEXTBEFORE(result_population!K11,",")) -> 2 | L11: =VALUE(_xlfn.TEXTBEFORE(result_population!L11,",")) -> 0 | M11: =VALUE(_xlfn.TEXTBEFORE(result_population!M11,",")) -> -13 | N11: =result_population__818[[#This Row],[Constr1]] -> 1 | R11: =VALUE(_xlfn.TEXTBEFORE(result_population!R11,",")) -> 0 | S11: =VALUE(_xlfn.TEXTBEFORE(result_population!S11,",")) -> 92 | T11: =VALUE(_xlfn.TEXTBEFORE(result_population!V11,",")) -> -44 | U11: =VALUE(_xlfn.TEXTBEFORE(result_population!W11,",")) -> -22 | V11: =result_population__411[[#This Row],[Constr1]] -> 2
B12: =VALUE(_xlfn.TEXTBEFORE(result_population!B12,",")) -> 4 | C12: =VALUE(_xlfn.TEXTBEFORE(result_population!C12,",")) -> 3 | D12: =VALUE(_xlfn.TEXTBEFORE(result_population!D12,",")) -> 3 | E12: =VALUE(_xlfn.TEXTBEFORE(result_population!E12,",")) -> -14 | F12: =result_population__614[[#This Row],[Constr1]] -> 2 | J12: =VALUE(_xlfn.TEXTBEFORE(result_population!J12,",")) -> 4 | K12: =VALUE(_xlfn.TEXTBEFORE(result_population!K12,",")) -> 9 | L12: =VALUE(_xlfn.TEXTBEFORE(result_population!L12,",")) -> 0 | M12: =VALUE(_xlfn.TEXTBEFORE(result_population!M12,",")) -> -20 | N12: =result_population__818[[#This Row],[Constr1]] -> 2 | R12: =VALUE(_xlfn.TEXTBEFORE(result_population!R12,",")) -> 8 | S12: =VALUE(_xlfn.TEXTBEFORE(result_population!S12,",")) -> 6 | T12: =VALUE(_xlfn.TEXTBEFORE(result_population!V12,",")) -> -23 | U12: =VALUE(_xlfn.TEXTBEFORE(result_population!W12,",")) -> -22 | V12: =result_population__411[[#This Row],[Constr1]] -> 3
B13: =VALUE(_xlfn.TEXTBEFORE(result_population!B13,",")) -> 2 | C13: =VALUE(_xlfn.TEXTBEFORE(result_population!C13,",")) -> 6 | D13: =VALUE(_xlfn.TEXTBEFORE(result_population!D13,",")) -> 0 | E13: =VALUE(_xlfn.TEXTBEFORE(result_population!E13,",")) -> -17 | F13: =result_population__614[[#This Row],[Constr1]] -> 7 | J13: =VALUE(_xlfn.TEXTBEFORE(result_population!J13,",")) -> 2 | K13: =VALUE(_xlfn.TEXTBEFORE(result_population!K13,",")) -> 8 | L13: =VALUE(_xlfn.TEXTBEFORE(result_population!L13,",")) -> -3 | M13: =VALUE(_xlfn.TEXTBEFORE(result_population!M13,",")) -> -17 | N13: =result_population__818[[#This Row],[Constr1]] -> 1 | R13: =VALUE(_xlfn.TEXTBEFORE(result_population!R13,",")) -> 13 | S13: =VALUE(_xlfn.TEXTBEFORE(result_population!S13,",")) -> 2 | T13: =VALUE(_xlfn.TEXTBEFORE(result_population!V13,",")) -> -22 | U13: =VALUE(_xlfn.TEXTBEFORE(result_population!W13,",")) -> -22 | V13: =result_population__411[[#This Row],[Constr1]] -> 5
B14: =VALUE(_xlfn.TEXTBEFORE(result_population!B14,",")) -> 0 | C14: =VALUE(_xlfn.TEXTBEFORE(result_population!C14,",")) -> 1 | D14: =VALUE(_xlfn.TEXTBEFORE(result_population!D14,",")) -> 0 | E14: =VALUE(_xlfn.TEXTBEFORE(result_population!E14,",")) -> -12 | F14: =result_population__614[[#This Row],[Constr1]] -> 7 | J14: =VALUE(_xlfn.TEXTBEFORE(result_population!J14,",")) -> 0 | K14: =VALUE(_xlfn.TEXTBEFORE(result_population!K14,",")) -> 4 | L14: =VALUE(_xlfn.TEXTBEFORE(result_population!L14,",")) -> -5 | M14: =VALUE(_xlfn.TEXTBEFORE(result_population!M14,",")) -> -14 | N14: =result_population__818[[#This Row],[Constr1]] -> 5 | R14: =VALUE(_xlfn.TEXTBEFORE(result_population!R14,",")) -> 15 | S14: =VALUE(_xlfn.TEXTBEFORE(result_population!S14,",")) -> 6 | T14: =VALUE(_xlfn.TEXTBEFORE(result_population!V14,",")) -> -30 | U14: =VALUE(_xlfn.TEXTBEFORE(result_population!W14,",")) -> -22 | V14: =result_population__411[[#This Row],[Constr1]] -> 2
... B94: =VALUE(_xlfn.TEXTBEFORE(result_population!B94,",")) -> 2 | C94: =VALUE(_xlfn.TEXTBEFORE(result_population!C94,",")) -> 2 | D94: =VALUE(_xlfn.TEXTBEFORE(result_population!D94,",")) -> 3 | E94: =VALUE(_xlfn.TEXTBEFORE(result_population!E94,",")) -> -12 | F94: =result_population__614[[#This Row],[Constr1]] -> 3 | J94: =VALUE(_xlfn.TEXTBEFORE(result_population!J94,",")) -> 2 | K94: =VALUE(_xlfn.TEXTBEFORE(result_population!K94,",")) -> 6 | L94: =VALUE(_xlfn.TEXTBEFORE(result_population!L94,",")) -> -4 | M94: =VALUE(_xlfn.TEXTBEFORE(result_population!M94,",")) -> -16 | N94: =result_population__818[[#This Row],[Constr1]] -> 3 | R94: =VALUE(_xlfn.TEXTBEFORE(result_population!R94,",")) -> 2 | S94: =VALUE(_xlfn.TEXTBEFORE(result_population!S94,",")) -> 34 | T94: =VALUE(_xlfn.TEXTBEFORE(result_population!V94,",")) -> -43 | U94: =VALUE(_xlfn.TEXTBEFORE(result_population!W94,",")) -> -22 | V94: =result_population__411[[#This Row],[Constr1]] -> 1
B95: =VALUE(_xlfn.TEXTBEFORE(result_population!B95,",")) -> 3 | C95: =VALUE(_xlfn.TEXTBEFORE(result_population!C95,",")) -> 5 | D95: =VALUE(_xlfn.TEXTBEFORE(result_population!D95,",")) -> 0 | E95: =VALUE(_xlfn.TEXTBEFORE(result_population!E95,",")) -> -16 | F95: =result_population__614[[#This Row],[Constr1]] -> 6 | J95: =VALUE(_xlfn.TEXTBEFORE(result_population!J95,",")) -> 1 | K95: =VALUE(_xlfn.TEXTBEFORE(result_population!K95,",")) -> 6 | L95: =VALUE(_xlfn.TEXTBEFORE(result_population!L95,",")) -> -5 | M95: =VALUE(_xlfn.TEXTBEFORE(result_population!M95,",")) -> -15 | N95: =result_population__818[[#This Row],[Constr1]] -> 3
B96: =VALUE(_xlfn.TEXTBEFORE(result_population!B96,",")) -> 1 | C96: =VALUE(_xlfn.TEXTBEFORE(result_population!C96,",")) -> 1 | D96: =VALUE(_xlfn.TEXTBEFORE(result_population!D96,",")) -> 0 | E96: =VALUE(_xlfn.TEXTBEFORE(result_population!E96,",")) -> -8 | F96: =result_population__614[[#This Row],[Constr1]] -> 2 | J96: =VALUE(_xlfn.TEXTBEFORE(result_population!J96,",")) -> 1 | K96: =VALUE(_xlfn.TEXTBEFORE(result_population!K96,",")) -> 1 | L96: =VALUE(_xlfn.TEXTBEFORE(result_population!L96,",")) -> -3 | M96: =VALUE(_xlfn.TEXTBEFORE(result_population!M96,",")) -> -12 | N96: =result_population__818[[#This Row],[Constr1]] -> 4
B97: =VALUE(_xlfn.TEXTBEFORE(result_population!B97,",")) -> 0 | C97: =VALUE(_xlfn.TEXTBEFORE(result_population!C97,",")) -> 6 | D97: =VALUE(_xlfn.TEXTBEFORE(result_population!D97,",")) -> 0 | E97: =VALUE(_xlfn.TEXTBEFORE(result_population!E97,",")) -> -12 | F97: =result_population__614[[#This Row],[Constr1]] -> 1
B98: =VALUE(_xlfn.TEXTBEFORE(result_population!B98,",")) -> 0 | C98: =VALUE(_xlfn.TEXTBEFORE(result_population!C98,",")) -> 3 | D98: =VALUE(_xlfn.TEXTBEFORE(result_population!D98,",")) -> 0 | E98: =VALUE(_xlfn.TEXTBEFORE(result_population!E98,",")) -> -8 | F98: =result_population__614[[#This Row],[Constr1]] -> 1
B99: =VALUE(_xlfn.TEXTBEFORE(result_population!B99,",")) -> 2 | C99: =VALUE(_xlfn.TEXTBEFORE(result_population!C99,",")) -> 2 | D99: =VALUE(_xlfn.TEXTBEFORE(result_population!D99,",")) -> 3 | E99: =VALUE(_xlfn.TEXTBEFORE(result_population!E99,",")) -> -11 | F99: =result_population__614[[#This Row],[Constr1]] -> 2
B100: =VALUE(_xlfn.TEXTBEFORE(result_population!B100,",")) -> 1 | C100: =VALUE(_xlfn.TEXTBEFORE(result_population!C100,",")) -> 1 | D100: =VALUE(_xlfn.TEXTBEFORE(result_population!D100,",")) -> 0 | E100: =VALUE(_xlfn.TEXTBEFORE(result_population!E100,",")) -> -11 | F100: =result_population__614[[#This Row],[Constr1]] -> 5
B101: =VALUE(_xlfn.TEXTBEFORE(result_population!B101,",")) -> 1 | C101: =VALUE(_xlfn.TEXTBEFORE(result_population!C101,",")) -> 3 | D101: =VALUE(_xlfn.TEXTBEFORE(result_population!D101,",")) -> 0 | E101: =VALUE(_xlfn.TEXTBEFORE(result_population!E101,",")) -> -13 | F101: =result_population__614[[#This Row],[Constr1]] -> 5
B102: =VALUE(_xlfn.TEXTBEFORE(result_population!B102,",")) -> 2 | C102: =VALUE(_xlfn.TEXTBEFORE(result_population!C102,",")) -> 6 | D102: =VALUE(_xlfn.TEXTBEFORE(result_population!D102,",")) -> 0 | E102: =VALUE(_xlfn.TEXTBEFORE(result_population!E102,",")) -> -15 | F102: =result_population__614[[#This Row],[Constr1]] -> 5

Sheet result_population
A1: SOC MIN | B1: ownerAndPetAreNotFriends | C1: notEnoughFriendsForPerson | D1: beingInFriendTriangle | E1: size | F1: personWithMoreThan2Dogs or dogWithoutOwner | I1: SOC_MAX | J1: ownerAndPetAreNotFriends | K1: notEnoughFriendsForPerson | L1: beingInFriendTriangle | M1: size | N1: personWithMoreThan2Dogs or dogWithoutOwner | Q1: CRA | R1: interClassDependency | S1: inClassNoDependency | T1: featureHasNoClass | U1: featureInMultipleClasses | V1: inClassDependency | W1: size | X1: featureHasNoClass
A2: version, | B2: Obj1, | C2: Obj2, | D2: Obj3, | E2: Obj5, | F2: Constr1 | I2: version, | J2: Obj1, | K2: Obj2, | L2: Obj4, | M2: Obj5, | N2: Constr1 | Q2: version, | R2: Obj1, | S2: Obj2, | T2: Obj3, | U2: Obj4, | V2: Obj5, | W2: Obj6, | X2: Constr1
A3: tools.refinery.store.dse.evolutionary.VersionVariable@e1b8f160, | B3: 0,000000, | C3: 2,000000, | D3: 0,000000, | E3: -7,000000, | F3: 1 | I3: tools.refinery.store.dse.evolutionary.VersionVariable@f91f1e0c, | J3: 0,000000, | K3: 1,000000, | L3: -5,000000, | M3: -8,000000, | N3: 1 | Q3: tools.refinery.store.dse.evolutionary.VersionVariable@9ead27f4, | R3: 0,000000, | S3: 200,000000, | T3: 0,000000, | U3: 0,000000, | V3: -47,000000, | W3: -22,000000, | X3: 0
A4: tools.refinery.store.dse.evolutionary.VersionVariable@b7c1ce97, | B4: 0,000000, | C4: 1,000000, | D4: 0,000000, | E4: -6,000000, | F4: 1 | I4: tools.refinery.store.dse.evolutionary.VersionVariable@de4ec8d7, | J4: 3,000000, | K4: 2,000000, | L4: -6,000000, | M4: -12,000000, | N4: 1 | Q4: tools.refinery.store.dse.evolutionary.VersionVariable@ea404534, | R4: 9,000000, | S4: 2,000000, | T4: 6,000000, | U4: 0,000000, | V4: -15,000000, | W4: -22,000000, | X4: 6
A5: tools.refinery.store.dse.evolutionary.VersionVariable@2f19fb8, | B5: 4,000000, | C5: 10,000000, | D5: 0,000000, | E5: -18,000000, | F5: 1 | I5: tools.refinery.store.dse.evolutionary.VersionVariable@e0a642bf, | J5: 5,000000, | K5: 9,000000, | L5: 0,000000, | M5: -20,000000, | N5: 1 | Q5: tools.refinery.store.dse.evolutionary.VersionVariable@a5fad7f9, | R5: 7,000000, | S5: 2,000000, | T5: 7,000000, | U5: 0,000000, | V5: -17,000000, | W5: -22,000000, | X5: 7
A6: tools.refinery.store.dse.evolutionary.VersionVariable@eda739cb, | B6: 0,000000, | C6: 1,000000, | D6: 0,000000, | E6: -13,000000, | F6: 8 | I6: tools.refinery.store.dse.evolutionary.VersionVariable@e6fbf862, | J6: 1,000000, | K6: 3,000000, | L6: 0,000000, | M6: -15,000000, | N6: 4 | Q6: tools.refinery.store.dse.evolutionary.VersionVariable@f8c6167e, | R6: 0,000000, | S6: 4,000000, | T6: 7,000000, | U6: 0,000000, | V6: -21,000000, | W6: -22,000000, | X6: 7
A7: tools.refinery.store.dse.evolutionary.VersionVariable@dbde9e30, | B7: 3,000000, | C7: 9,000000, | D7: 3,000000, | E7: -18,000000, | F7: 1 | G7: !!! 4 | I7: tools.refinery.store.dse.evolutionary.VersionVariable@8dbf6e6, | J7: 0,000000, | K7: 2,000000, | L7: -4,000000, | M7: -14,000000, | N7: 8 | Q7: tools.refinery.store.dse.evolutionary.VersionVariable@f968a3ae, | R7: 16,000000, | S7: 10,000000, | T7: 0,000000, | U7: 0,000000, | V7: -31,000000, | W7: -22,000000, | X7: 0
A8: tools.refinery.store.dse.evolutionary.VersionVariable@ee57974b, | B8: 8,000000, | C8: 6,000000, | D8: 0,000000, | E8: -18,000000, | F8: 2 | I8: tools.refinery.store.dse.evolutionary.VersionVariable@de9c507f, | J8: 5,000000, | K8: 2,000000, | L8: -5,000000, | M8: -14,000000, | N8: 2 | Q8: tools.refinery.store.dse.evolutionary.VersionVariable@8dc3ba92, | R8: 0,000000, | S8: 170,000000, | T8: 1,000000, | U8: 0,000000, | V8: -46,000000, | W8: -22,000000, | X8: 1
A9: tools.refinery.store.dse.evolutionary.VersionVariable@94dd8f48, | B9: 1,000000, | C9: 1,000000, | D9: 3,000000, | E9: -8,000000, | F9: 1 | I9: tools.refinery.store.dse.evolutionary.VersionVariable@c3636b18, | J9: 1,000000, | K9: 4,000000, | L9: -3,000000, | M9: -16,000000, | N9: 5 | Q9: tools.refinery.store.dse.evolutionary.VersionVariable@278b679, | R9: 1,000000, | S9: 118,000000, | T9: 0,000000, | U9: 0,000000, | V9: -46,000000, | W9: -22,000000, | X9: 0
A10: tools.refinery.store.dse.evolutionary.VersionVariable@b53cc39a, | B10: 2,000000, | C10: 8,000000, | D10: 3,000000, | E10: -17,000000, | F10: 2 | I10: tools.refinery.store.dse.evolutionary.VersionVariable@96ec96fd, | J10: 2,000000, | K10: 5,000000, | L10: -4,000000, | M10: -17,000000, | N10: 6 | Q10: tools.refinery.store.dse.evolutionary.VersionVariable@b7995b53, | R10: 0,000000, | S10: 70,000000, | T10: 3,000000, | U10: 0,000000, | V10: -43,000000, | W10: -22,000000, | X10: 3
A11: tools.refinery.store.dse.evolutionary.VersionVariable@90bf3123, | B11: 2,000000, | C11: 2,000000, | D11: 3,000000, | E11: -13,000000, | F11: 4 | I11: tools.refinery.store.dse.evolutionary.VersionVariable@a590ea7d, | J11: 3,000000, | K11: 2,000000, | L11: 0,000000, | M11: -13,000000, | N11: 1 | Q11: tools.refinery.store.dse.evolutionary.VersionVariable@9667c13a, | R11: 0,000000, | S11: 92,000000, | T11: 2,000000, | U11: 0,000000, | V11: -44,000000, | W11: -22,000000, | X11: 2
A12: tools.refinery.store.dse.evolutionary.VersionVariable@af2c8019, | B12: 4,000000, | C12: 3,000000, | D12: 3,000000, | E12: -14,000000, | F12: 2 | I12: tools.refinery.store.dse.evolutionary.VersionVariable@acb4e3ef, | J12: 4,000000, | K12: 9,000000, | L12: 0,000000, | M12: -20,000000, | N12: 2 | Q12: tools.refinery.store.dse.evolutionary.VersionVariable@b93d449a, | R12: 8,000000, | S12: 6,000000, | T12: 3,000000, | U12: 0,000000, | V12: -23,000000, | W12: -22,000000, | X12: 3
A13: tools.refinery.store.dse.evolutionary.VersionVariable@e2389f43, | B13: 2,000000, | C13: 6,000000, | D13: 0,000000, | E13: -17,000000, | F13: 7 | I13: tools.refinery.store.dse.evolutionary.VersionVariable@c8d6f204, | J13: 2,000000, | K13: 8,000000, | L13: -3,000000, | M13: -17,000000, | N13: 1 | Q13: tools.refinery.store.dse.evolutionary.VersionVariable@a23fd59f, | R13: 13,000000, | S13: 2,000000, | T13: 5,000000, | U13: 0,000000, | V13: -22,000000, | W13: -22,000000, | X13: 5
A14: tools.refinery.store.dse.evolutionary.VersionVariable@a5b913ba, | B14: 0,000000, | C14: 1,000000, | D14: 0,000000, | E14: -12,000000, | F14: 7 | I14: tools.refinery.store.dse.evolutionary.VersionVariable@e5c2beb5, | J14: 0,000000, | K14: 4,000000, | L14: -5,000000, | M14: -14,000000, | N14: 5 | Q14: tools.refinery.store.dse.evolutionary.VersionVariable@eab9b622, | R14: 15,000000, | S14: 6,000000, | T14: 2,000000, | U14: 0,000000, | V14: -30,000000, | W14: -22,000000, | X14: 2
A15: tools.refinery.store.dse.evolutionary.VersionVariable@a1d75523, | B15: 0,000000, | C15: 1,000000, | D15: 0,000000, | E15: -10,000000, | F15: 5 | I15: tools.refinery.store.dse.evolutionary.VersionVariable@e0a9470d, | J15: 5,000000, | K15: 7,000000, | L15: -4,000000, | M15: -18,000000, | N15: 1 | Q15: tools.refinery.store.dse.evolutionary.VersionVariable@b3fcf11a, | R15: 15,000000, | S15: 8,000000, | T15: 1,000000, | U15: 0,000000, | V15: -31,000000, | W15: -22,000000, | X15: 1
A16: tools.refinery.store.dse.evolutionary.VersionVariable@d9e2a9e9, | B16: 0,000000, | C16: 1,000000, | D16: 0,000000, | E16: -8,000000, | F16: 3 | I16: tools.refinery.store.dse.evolutionary.VersionVariable@ced21f53, | J16: 3,000000, | K16: 1,000000, | L16: -5,000000, | M16: -11,000000, | N16: 1 | Q16: tools.refinery.store.dse.evolutionary.VersionVariable@fffd07de, | R16: 2,000000, | S16: 54,000000, | T16: 0,000000, | U16: 0,000000, | V16: -45,000000, | W16: -22,000000, | X16: 0
A17: tools.refinery.store.dse.evolutionary.VersionVariable@d03a8987, | B17: 0,000000, | C17: 1,000000, | D17: 0,000000, | E17: -7,000000, | F17: 2 | I17: tools.refinery.store.dse.evolutionary.VersionVariable@c577c20d, | J17: 1,000000, | K17: 6,000000, | L17: -4,000000, | M17: -16,000000, | N17: 4 | Q17: tools.refinery.store.dse.evolutionary.VersionVariable@f0445db8, | R17: 0,000000, | S17: 8,000000, | T17: 6,000000, | U17: 0,000000, | V17: -30,000000, | W17: -22,000000, | X17: 6
A18: tools.refinery.store.dse.evolutionary.VersionVariable@92335246, | B18: 0,000000, | C18: 1,000000, | D18: 0,000000, | E18: -9,000000, | F18: 4 | I18: tools.refinery.store.dse.evolutionary.VersionVariable@1ea6e98, | J18: 0,000000, | K18: 1,000000, | L18: -3,000000, | M18: -12,000000, | N18: 5 | Q18: tools.refinery.store.dse.evolutionary.VersionVariable@daa6233e, | R18: 0,000000, | S18: 12,000000, | T18: 5,000000, | U18: 0,000000, | V18: -35,000000, | W18: -22,000000, | X18: 5
A19: tools.refinery.store.dse.evolutionary.VersionVariable@de55bc8c, | B19: 0,000000, | C19: 1,000000, | D19: 0,000000, | E19: -11,000000, | F19: 6 | I19: tools.refinery.store.dse.evolutionary.VersionVariable@6cfe2a7, | J19: 0,000000, | K19: 1,000000, | L19: -5,000000, | M19: -9,000000, | N19: 2 | Q19: tools.refinery.store.dse.evolutionary.VersionVariable@9582fe7f, | R19: 0,000000, | S19: 22,000000, | T19: 4,000000, | U19: 0,000000, | V19: -38,000000, | W19: -22,000000, | X19: 4
... A52: tools.refinery.store.dse.evolutionary.VersionVariable@710451c, | B52: 1,000000, | C52: 1,000000, | D52: 0,000000, | E52: -7,000000, | F52: 1 | I52: tools.refinery.store.dse.evolutionary.VersionVariable@9ae2703f, | J52: 0,000000, | K52: 3,000000, | L52: -5,000000, | M52: -13,000000, | N52: 4 | Q52: tools.refinery.store.dse.evolutionary.VersionVariable@2252f8, | R52: 0,000000, | S52: 36,000000, | T52: 2,000000, | U52: 0,000000, | V52: -34,000000, | W52: -22,000000, | X52: 2
A53: tools.refinery.store.dse.evolutionary.VersionVariable@fa7d5733, | B53: 1,000000, | C53: 2,000000, | D53: 0,000000, | E53: -10,000000, | F53: 1 | I53: tools.refinery.store.dse.evolutionary.VersionVariable@bf1578fe, | J53: 5,000000, | K53: 3,000000, | L53: -5,000000, | M53: -15,000000, | N53: 2 | P53: !!! 50 | Q53: tools.refinery.store.dse.evolutionary.VersionVariable@af0030fc, | R53: 4,000000, | S53: 34,000000, | T53: 0,000000, | U53: 0,000000, | V53: -43,000000, | W53: -22,000000, | X53: 0
A54: tools.refinery.store.dse.evolutionary.VersionVariable@b3d69d34, | B54: 2,000000, | C54: 5,000000, | D54: 0,000000, | E54: -16,000000, | F54: 7 | I54: tools.refinery.store.dse.evolutionary.VersionVariable@69cfcb1, | J54: 5,000000, | K54: 2,000000, | L54: -5,000000, | M54: -13,000000, | N54: 1 | Q54: tools.refinery.store.dse.evolutionary.VersionVariable@a06f4c36, | R54: 0,000000, | S54: 6,000000, | T54: 6,000000, | U54: 0,000000, | V54: -22,000000, | W54: -22,000000, | X54: 6
A55: tools.refinery.store.dse.evolutionary.VersionVariable@cffcbca5, | B55: 4,000000, | C55: 7,000000, | D55: 0,000000, | E55: -17,000000, | F55: 4 | I55: tools.refinery.store.dse.evolutionary.VersionVariable@f816ff3f, | J55: 4,000000, | K55: 4,000000, | L55: -5,000000, | M55: -14,000000, | N55: 1 | Q55: tools.refinery.store.dse.evolutionary.VersionVariable@8bf77cfa, | R55: 0,000000, | S55: 14,000000, | T55: 4,000000, | U55: 0,000000, | V55: -36,000000, | W55: -22,000000, | X55: 4
A56: tools.refinery.store.dse.evolutionary.VersionVariable@b9bb39b3, | B56: 7,000000, | C56: 6,000000, | D56: 0,000000, | E56: -17,000000, | F56: 2 | I56: tools.refinery.store.dse.evolutionary.VersionVariable@ec27aa5b, | J56: 1,000000, | K56: 2,000000, | L56: -5,000000, | M56: -11,000000, | N56: 1 | Q56: tools.refinery.store.dse.evolutionary.VersionVariable@f242ef3e, | R56: 1,000000, | S56: 20,000000, | T56: 4,000000, | U56: 0,000000, | V56: -39,000000, | W56: -22,000000, | X56: 4
